Traceback (most recent call last):
  File "/media/colin/Shared/colin/git/materials-ml-workshop/env/lib/python3.10/site-packages/jupyter_cache/executors/utils.py", line 58, in single_nb_execution
    executenb(
  File "/media/colin/Shared/colin/git/materials-ml-workshop/env/lib/python3.10/site-packages/nbclient/client.py", line 1305, in execute
    return NotebookClient(nb=nb, resources=resources, km=km, **kwargs).execute()
  File "/media/colin/Shared/colin/git/materials-ml-workshop/env/lib/python3.10/site-packages/jupyter_core/utils/__init__.py", line 166, in wrapped
    return loop.run_until_complete(inner)
  File "/usr/lib/python3.10/asyncio/base_events.py", line 646, in run_until_complete
    return future.result()
  File "/media/colin/Shared/colin/git/materials-ml-workshop/env/lib/python3.10/site-packages/nbclient/client.py", line 705, in async_execute
    await self.async_execute_cell(
  File "/media/colin/Shared/colin/git/materials-ml-workshop/env/lib/python3.10/site-packages/nbclient/client.py", line 1058, in async_execute_cell
    await self._check_raise_for_error(cell, cell_index, exec_reply)
  File "/media/colin/Shared/colin/git/materials-ml-workshop/env/lib/python3.10/site-packages/nbclient/client.py", line 914, in _check_raise_for_error
    raise CellExecutionError.from_cell_and_msg(cell, exec_reply_content)
nbclient.exceptions.CellExecutionError: An error occurred while executing the following cell:
------------------
from scipy.stats import gaussian_kde

# fit a kde model to the data:
kde = gaussian_kde(data_x.T)

# define 2D mesh grid:
x1_pts = np.linspace(-3.5,6.5,100)
x2_pts = np.linspace(-6.5,6.5,100)
x1_mesh, x2_mesh = np.meshgrid(x1_pts, x2_pts)
x_mesh = np.vstack([x1_mesh.flatten(), x2_mesh.flatten()]).T

# evaluate kde probability density on mesh points:
prob_mesh = kde(x12_mesh.T).reshape(x1_mesh.shape)

# plot distribution:
plt.figure()
plt.contourf(x1_mesh, x2_mesh, prob_mesh, levels=10, cmap='Greys')
plt.colorbar(label='p(x)')
plt.scatter(data_x[:,0], data_x[:,1], label=f'Dataset', alpha=0.3)
plt.xlabel(r'$x_1$')
plt.ylabel(r'$x_2$')
plt.show()

------------------


[0;31m---------------------------------------------------------------------------[0m
[0;31mNameError[0m                                 Traceback (most recent call last)
Cell [0;32mIn[5], line 13[0m
[1;32m     10[0m x_mesh [38;5;241m=[39m np[38;5;241m.[39mvstack([x1_mesh[38;5;241m.[39mflatten(), x2_mesh[38;5;241m.[39mflatten()])[38;5;241m.[39mT
[1;32m     12[0m [38;5;66;03m# evaluate kde probability density on mesh points:[39;00m
[0;32m---> 13[0m prob_mesh [38;5;241m=[39m kde([43mx12_mesh[49m[38;5;241m.[39mT)[38;5;241m.[39mreshape(x1_mesh[38;5;241m.[39mshape)
[1;32m     15[0m [38;5;66;03m# plot distribution:[39;00m
[1;32m     16[0m plt[38;5;241m.[39mfigure()

[0;31mNameError[0m: name 'x12_mesh' is not defined

