Traceback (most recent call last):
  File "/media/colin/Shared/colin/git/materials-ml-workshop/env/lib/python3.10/site-packages/jupyter_cache/executors/utils.py", line 58, in single_nb_execution
    executenb(
  File "/media/colin/Shared/colin/git/materials-ml-workshop/env/lib/python3.10/site-packages/nbclient/client.py", line 1305, in execute
    return NotebookClient(nb=nb, resources=resources, km=km, **kwargs).execute()
  File "/media/colin/Shared/colin/git/materials-ml-workshop/env/lib/python3.10/site-packages/jupyter_core/utils/__init__.py", line 166, in wrapped
    return loop.run_until_complete(inner)
  File "/usr/lib/python3.10/asyncio/base_events.py", line 649, in run_until_complete
    return future.result()
  File "/media/colin/Shared/colin/git/materials-ml-workshop/env/lib/python3.10/site-packages/nbclient/client.py", line 705, in async_execute
    await self.async_execute_cell(
  File "/media/colin/Shared/colin/git/materials-ml-workshop/env/lib/python3.10/site-packages/nbclient/client.py", line 1058, in async_execute_cell
    await self._check_raise_for_error(cell, cell_index, exec_reply)
  File "/media/colin/Shared/colin/git/materials-ml-workshop/env/lib/python3.10/site-packages/nbclient/client.py", line 914, in _check_raise_for_error
    raise CellExecutionError.from_cell_and_msg(cell, exec_reply_content)
nbclient.exceptions.CellExecutionError: An error occurred while executing the following cell:
------------------
import matplotlib.pyplot as plt

eval_pts = np.linspace(-10, 10, 100)
eval_X1, eval_X2 = np.meshgrid(eval_pts, eval_pts)

eval_x = np.array([ eval_X1.flatten(), eval_X2.flatten() ]).T
eval_z = scaler.transform(eval_x)
eval_z_tensor = torch.tensor(eval_z, dtype=torch.float32)
eval_z = np.array(model(eval_z_tensor).detach().numpy())
model_yhat = eval_z.reshape(eval_X1.shape)

plt.figure(figsize=(10,4))
plt.subplot(1,3,1)
plt.scatter(data_x[:,0], data_x[:,1], c=data_y, s=0.5)
plt.title('Training Data')

plt.subplot(1,3,2)
plt.contourf(eval_X1, eval_X2, sinc_function(eval_X1,eval_X2), levels=100)
plt.title(r'Actual Function ($y$)')

plt.subplot(1,3,3)
plt.title('Neural Network ($\hat{y}$)')
plt.contourf(eval_X1, eval_X2, model_yhat, levels=100)

plt.tight_layout()
plt.show()
------------------


[0;31m---------------------------------------------------------------------------[0m
[0;31mRuntimeError[0m                              Traceback (most recent call last)
Cell [0;32mIn[9], line 9[0m
[1;32m      7[0m eval_z [38;5;241m=[39m scaler[38;5;241m.[39mtransform(eval_x)
[1;32m      8[0m eval_z_tensor [38;5;241m=[39m torch[38;5;241m.[39mtensor(eval_z, dtype[38;5;241m=[39mtorch[38;5;241m.[39mfloat32)
[0;32m----> 9[0m eval_z [38;5;241m=[39m np[38;5;241m.[39marray([43mmodel[49m[43m([49m[43meval_z_tensor[49m[43m)[49m[38;5;241;43m.[39;49m[43mdetach[49m[43m([49m[43m)[49m[38;5;241;43m.[39;49m[43mnumpy[49m[43m([49m[43m)[49m)
[1;32m     10[0m model_yhat [38;5;241m=[39m eval_z[38;5;241m.[39mreshape(eval_X1[38;5;241m.[39mshape)
[1;32m     12[0m plt[38;5;241m.[39mfigure(figsize[38;5;241m=[39m([38;5;241m10[39m,[38;5;241m4[39m))

[0;31mRuntimeError[0m: Numpy is not available

